<mujoco model="single_fingertip_scene">
    <visual>
        <global offwidth="1280" offheight="960"/>
    </visual>
    <compiler angle="radian"/>
    <size njmax="500" nconmax="100"/>
    <asset>
        <mesh name="object" file="../assets/objects/bunny.stl" scale="0.8 0.8 0.8"/>
       <texture name="cube_surface" file="../assets/textures/iris_block.png" gridsize="3 4" gridlayout=".U..LFRB.D.."/>
       <material name="obj_material" texture="cube_surface" specular="15" shininess="0.0"/>
        <texture type="2d" name="groundplane" builtin="checker" mark="edge" rgb1="0.2 0.3 0.4"
        rgb2="0.1 0.2 0.3" markrgb="0.8 0.8 0.8" width="300" height="300"/>
        <material name="groundplane" texture="groundplane" texuniform="true" texrepeat="5 5"
        reflectance="0.0"/>
    </asset>

    <worldbody>
        <light directional="true" ambient="0.6 0.6 0.6" diffuse="0.8 0.8 0.8"
               castshadow="false" pos="0 1 4" dir="0 0 -1" name="light0"/>

        <!-- Example cameras (optional) -->
        <camera name="demo-cam"  pos="0.086 -0.324 0.157" xyaxes="0.966 0.259 0.000 -0.102 0.380 0.919"/>
        <camera name="demo-cam2" pos="-0.003 -0.654 0.316" xyaxes="1.000 -0.005 0.000 0.002 0.435 0.900"/>
        <camera name="demo-cam3" pos="0.010 -0.385 0.122" xyaxes="1.000 -0.004 0.000 0.001 0.208 0.978"/>

        <!-- ============================= Virtual object (goal) ========================================= -->
        <!-- <body name="goal" pos="0.0 0.0 0.03">
            <geom name="goal" size="0.030 0.030 0.030" material="obj_material" type="box"
                  conaffinity="0" contype="0" rgba="1 1 1 0.3"/>
            <geom name="goal-decoration" size="0.030 0.030 0.030" type="box"
                  conaffinity="0" contype="0" rgba="0 1 0 0.2"/>
        </body> -->
        <body name="goal" >
            <geom name="goal" type="mesh" mesh="object" conaffinity="0" contype="0"
                pos="0.015 0.0 -0.005" quat="1 0 0 0"
                rgba="0.0 0.5 0.0 0.3"/>
        </body>
        <!-- ============================= Real object ========================================= -->
        <body name="obj" >
            <freejoint name="object_table"/>
            <geom name="obj" type="mesh" mesh="object"
                pos="0.015 0.0 -0.005" quat="1 0 0 0"
                mass="0.01"
                condim="6"
                friction="0.9" rgba="0.5 0.5 0.5 1.0"/>
        </body>

        <!-- Table / ground plane -->
        <geom name="table" type="plane" material="groundplane"
              condim="6" friction="0.5"
              size="0 0 0.05" rgba="0.8 0.8 0.8 1.0"/>

        <!-- ============================= Single fingertip ============================= -->
        <body name="fingertip0" pos="0.0 0.0 0.0" quat="1 0 0 0">
            <!-- Three slide joints (x, y, z) -->
            <joint name="fingertip0_x" type="slide" axis="1 0 0"/>
            <joint name="fingertip0_y" type="slide" axis="0 1 0"/>
            <joint name="fingertip0_z" type="slide" axis="0 0 1"/>

            <!-- Geom for the fingertip -->
            <geom name="fingertip0" type="sphere" size="0.01"
                  condim="6"
                  pos="0.0 0.0 0.0" quat="1 0 0 0"
                  friction="0.5" rgba="0.5 0 0 1"/>
        </body>
    </worldbody>

    <actuator>
        <!-- Actuators controlling the single fingertip's x, y, and z slide joints -->
        <motor name="fingertip0_refx" joint="fingertip0_x" ctrlrange="-1.5 1.5" ctrllimited="false"/>
        <motor name="fingertip0_refy" joint="fingertip0_y" ctrlrange="-1.5 1.5" ctrllimited="false"/>
        <motor name="fingertip0_refz" joint="fingertip0_z" ctrlrange="-1.5 1.5" ctrllimited="false"/>
    </actuator>
</mujoco>
